Workbook

Sheet Anleitung
A1: Verteilerdokumentation
A2: So arbeitest du mit dieser Vorlage
A5: ABLAUF
A6: 1 | B6: Vorlage per Doppelklick öffnen – Excel legt eine neue Datei an. Gleich im Kundenordner speichern, z. B. als „JJJJ-MM-TT Verteilerdokumentation <Verteiler>.xlsx“.
A7: 2 | B7: Blatt „Anlage“: Kunde, Verteiler, Netz und Erdung ausfüllen. Diese Angaben erscheinen automatisch auf allen anderen Blättern.
A8: 3 | B8: Blatt „Stromkreisliste“: eine Zeile je Schutzorgan (FI, LS, Hauptschalter …). Reihe und Platz = Position im Verteiler (Reihe 1 oben, Platz 1 links, in Teilungseinheiten). Die Spalte „Beschriftung kurz“ wird zum Beschriftungsstreifen.
A9: 4 | B9: Blatt „Beschriftung“: füllt sich selbst. Mit 100 % drucken (keine Skalierung), ein Feld = 1 TE = 17,5 mm. Am Probedruck mit dem Lineal nachmessen, ausschneiden, in die Beschriftungsleiste des Verteilers schieben.
A10: 5 | B10: Blatt „Messprotokoll“: Messwerte je Stromkreis eintragen. Ik, Zs max und das Ergebnis rechnen sich selbst. Die Grenzwerte stehen oben im Blatt und lassen sich anpassen.
A11: 6 | B11: Blatt „Prüfbericht“: Besichtigen und Erproben abhaken, Mängel eintragen, Gesamtergebnis wählen, unterschreiben.
A12: 7 | B12: Für den Kunden: Stromkreisliste, Prüfbericht und Messprotokoll als PDF speichern (Datei › Exportieren) und mit der Kundendokumentation übergeben. Eine Kopie der Stromkreisliste gehört in den Verteiler.
A14: FARBEN
B15: Gelbe Zellen = deine Eingabe. Weiße Zellen = Formel, nicht überschreiben. Zeilen 7–9 der Stromkreisliste sind Beispiele – überschreiben oder löschen.
B16: Leere Zeilen beim Drucken ausblenden: in der Kopfzeile den Filter bei „BMK“ öffnen und „(Leere)“ abwählen.
A18: WICHTIG
B19: Die automatische Bewertung ist eine Hilfe, kein Ersatz für die Beurteilung durch die Elektrofachkraft. Maßgeblich sind DIN VDE 0100-600, DIN VDE 0105-100 und die Angaben der Gerätehersteller.

Sheet Anlage
A1: Verteilerdokumentation
A2: Anlagen- und Verteilerdaten
A4: Gelbe Felder ausfüllen – die Angaben erscheinen automatisch auf Stromkreisliste, Beschriftung, Prüfbericht und Messprotokoll.
A6: KUNDE UND OBJEKT
A7: Auftraggeber / Betreiber | B7: Familie Muster | C7: Kunden-Nr.
A8: Anlagenanschrift | B8: Musterstraße 12, 12345 Musterstadt
A9: Auftrags-Nr. | B9: 2026-014 | C9: Datum | D9: 46303
A11: VERTEILER
A12: Bezeichnung (z. B. UV EG) | B12: UV Wohnung 1. OG | C12: Standort | D12: Flur
A13: Hersteller / Typ | C13: Reihen × TE
A14: Zuleitung (Typ, Querschnitt) | B14: NYM-J 5×10 mm² | C14: Vorsicherung | D14: SLS E 35 A
A16: NETZ UND ERDUNG
A17: Netzbetreiber | C17: Zählernummer
A18: Netzsystem | B18: TN-C-S | C18: Nennspannung | D18: 230/400 V, 50 Hz
A19: Hausanschlusssicherung | C19: Hauptpotentialausgleich
A20: Überspannungsschutz | B20: Typ 2 | C20: Erdungswiderstand RA (Ω)
A21: Erdungsanlage
A23: ERRICHTER UND PRÜFER
A24: Errichter | B24: Muster Elektrotechnik GmbH · Max Mustermann, Elektrotechnikermeister · Musterstraße 1 · 12345 Musterstadt
A25: Installateurverzeichnis | C25: HWK-Betriebs-Nr.
A26: Prüfer | B26: Max Mustermann | C26: Telefon | D26: 0123 456789
A28: ZUSAMMENFASSUNG (AUTOMATISCH)
A29: Stromkreise erfasst | B29: =COUNTIF(Stromkreisliste!B7:B56,"?*") | C29: Stromkreise gemessen | D29: =COUNTIF(Messprotokoll!P7:P56,"?*")
A30: davon in Ordnung | B30: =COUNTIF(Messprotokoll!P7:P56,"i.O.") | C30: davon nicht in Ordnung | D30: =COUNTIF(Messprotokoll!P7:P56,"n.i.O.")
A31: Ergebnis der Messungen | B31: =IF(D30>0,"Mängel festgestellt – siehe Messprotokoll",IF(B30>0,"Alle gemessenen Stromkreise in Ordnung","noch keine Messwerte"))

Sheet Stromkreisliste
A1: Stromkreisliste
A2: Verteilerdokumentation · Muster Elektrotechnik GmbH
A4: Verteiler | C4: =IF(Anlage!B12="","",Anlage!B12&IF(Anlage!D12="",""," · "&Anlage!D12)) | G4: Objekt | J4: =IF(Anlage!B8="","",Anlage!B8) | P4: Auftraggeber | Q4: =IF(Anlage!B7="","",Anlage!B7) | R4: =IF(Anlage!D9="","",Anlage!D9)
A5: Eine Zeile je Schutzorgan. Reihe / Platz = Position im Verteiler (Reihe 1 oben, Platz 1 links) – daraus entsteht das Blatt „Beschriftung“. Zeilen 7–9 sind Beispiele: überschreiben oder löschen.
A6: Nr. | B6: BMK | C6: Reihe | D6: Platz (TE) | E6: Breite (TE) | F6: Schutzorgan | G6: Char. | H6: In (A) | I6: Pole | J6: vor-geschalteter FI | K6: IΔn (mA) | L6: FI-Typ | M6: Leitung | N6: Adern × mm² | O6: Länge ca. (m) | P6: Raum / Bereich | Q6: Verbraucher / Beschreibung | R6: Beschriftung kurz (max. 14 Zeichen) | S6: Schlüssel
A7: =IF(B7="","",ROW()-6) | B7: Q1 | C7: 1 | D7: 1 | E7: 3 | F7: Hauptschalter | H7: 63 | I7: 3 | R7: Hauptschalter | S7: =IF(OR(C7="",D7=""),"",C7&"-"&D7)
A8: =IF(B8="","",ROW()-6) | B8: F0 | C8: 1 | D8: 4 | E8: 4 | F8: Überspannungsschutz | I8: 4 | R8: Überspannung | S8: =IF(OR(C8="",D8=""),"",C8&"-"&D8)
A9: =IF(B9="","",ROW()-6) | B9: F1 | C9: 1 | D9: 8 | E9: 4 | F9: FI/RCD | H9: 40 | I9: 4 | K9: 30 | L9: A | R9: FI 40A 30mA | S9: =IF(OR(C9="",D9=""),"",C9&"-"&D9)
A10: =IF(B10="","",ROW()-6) | B10: F2 | C10: 1 | D10: 12 | E10: 1 | F10: LS | G10: B | H10: 16 | I10: 1 | J10: F1 | M10: NYM-J | N10: 3×2,5 | O10: 12 | P10: Küche | Q10: Steckdosen Arbeitsplatte links | R10: Küche SD AP li | S10: =IF(OR(C10="",D10=""),"",C10&"-"&D10)
A11: =IF(B11="","",ROW()-6) | B11: F3 | C11: 2 | D11: 1 | E11: 1 | F11: LS | G11: B | H11: 16 | I11: 1 | J11: F1 | M11: NYM-J | N11: 3×2,5 | O11: 14 | P11: Küche | Q11: Steckdosen Arbeitsplatte rechts | R11: Küche SD AP re | S11: =IF(OR(C11="",D11=""),"",C11&"-"&D11)
A12: =IF(B12="","",ROW()-6) | B12: F4 | C12: 2 | D12: 2 | E12: 1 | F12: LS | G12: B | H12: 16 | I12: 1 | J12: F1 | M12: NYM-J | N12: 3×2,5 | O12: 11 | P12: Küche | Q12: Geschirrspüler | R12: Küche GS | S12: =IF(OR(C12="",D12=""),"",C12&"-"&D12)
A13: =IF(B13="","",ROW()-6) | B13: F5 | C13: 2 | D13: 3 | E13: 1 | F13: LS | G13: B | H13: 16 | I13: 1 | J13: F1 | M13: NYM-J | N13: 3×1,5 | O13: 10 | P13: Küche | Q13: Kühlschrank, Dunstabzug | R13: Küche KS, Duns | S13: =IF(OR(C13="",D13=""),"",C13&"-"&D13)
A14: =IF(B14="","",ROW()-6) | B14: F6 | C14: 2 | D14: 4 | E14: 4 | F14: FI/RCD | H14: 40 | I14: 4 | K14: 30 | L14: A | R14: FI 40A 30mA | S14: =IF(OR(C14="",D14=""),"",C14&"-"&D14)
A15: =IF(B15="","",ROW()-6) | B15: F7 | C15: 2 | D15: 8 | E15: 1 | F15: LS | G15: B | H15: 10 | I15: 1 | J15: F6 | M15: NYM-J | N15: 3×1,5 | O15: 22 | P15: Flur | Q15: Licht Flur | R15: Li Flur | S15: =IF(OR(C15="",D15=""),"",C15&"-"&D15)
A16: =IF(B16="","",ROW()-6) | B16: F8 | C16: 2 | D16: 9 | E16: 1 | F16: LS | G16: B | H16: 16 | I16: 1 | J16: F6 | M16: NYM-J | N16: 3×1,5 | O16: 18 | P16: Wohnzimmer | Q16: Steckdosen und Licht | R16: Wohnzi. SD und | S16: =IF(OR(C16="",D16=""),"",C16&"-"&D16)
A17: =IF(B17="","",ROW()-6) | B17: F9 | C17: 2 | D17: 10 | E17: 1 | F17: LS | G17: B | H17: 16 | I17: 1 | J17: F6 | M17: NYM-J | N17: 3×1,5 | O17: 20 | P17: Schlafzimmer | Q17: Steckdosen und Licht | R17: Schlafzi. SD u | S17: =IF(OR(C17="",D17=""),"",C17&"-"&D17)
A18: =IF(B18="","",ROW()-6) | B18: F10 | C18: 2 | D18: 11 | E18: 1 | F18: LS | G18: B | H18: 16 | I18: 1 | J18: F6 | M18: NYM-J | N18: 3×2,5 | O18: 9 | P18: Bad | Q18: Steckdosen Bad, Spiegelschrank | R18: SD Bad, Spiege | S18: =IF(OR(C18="",D18=""),"",C18&"-"&D18)
A19: =IF(B19="","",ROW()-6) | B19: F11 | C19: 3 | D19: 1 | E19: 3 | F19: LS | G19: B | H19: 16 | I19: 3 | J19: F6 | M19: NYM-J | N19: 5×2,5 | O19: 12 | P19: Küche | Q19: Herd / Kochfeld | R19: Küche Herd | S19: =IF(OR(C19="",D19=""),"",C19&"-"&D19)
A20: =IF(B20="","",ROW()-6) | B20: F12 | C20: 3 | D20: 4 | E20: 2 | F20: FI/LS (RCBO) | G20: B | H20: 16 | I20: 2 | K20: 30 | L20: A | M20: NYM-J | N20: 3×2,5 | O20: 8 | P20: Bad | Q20: Waschmaschine | R20: Bad WM | S20: =IF(OR(C20="",D20=""),"",C20&"-"&D20)
A21: =IF(B21="","",ROW()-6) | B21: F13 | C21: 3 | D21: 6 | E21: 2 | F21: FI/LS (RCBO) | G21: B | H21: 16 | I21: 2 | K21: 30 | L21: A | M21: NYM-J | N21: 3×2,5 | O21: 15 | P21: Balkon | Q21: Außensteckdose IP44 | R21: Balkon Außen S | S21: =IF(OR(C21="",D21=""),"",C21&"-"&D21)
A22: =IF(B22="","",ROW()-6) | B22: F14 | C22: 3 | D22: 8 | E22: 3 | F22: LS | G22: B | H22: 32 | I22: 3 | M22: NYM-J | N22: 5×6 | O22: 9 | P22: Bad | Q22: Durchlauferhitzer 21 kW | R22: Bad DLE 21 kW | S22: =IF(OR(C22="",D22=""),"",C22&"-"&D22)
A23: =IF(B23="","",ROW()-6) | S23: =IF(OR(C23="",D23=""),"",C23&"-"&D23)
A24: =IF(B24="","",ROW()-6) | S24: =IF(OR(C24="",D24=""),"",C24&"-"&D24)
A25: =IF(B25="","",ROW()-6) | S25: =IF(OR(C25="",D25=""),"",C25&"-"&D25)
A26: =IF(B26="","",ROW()-6) | S26: =IF(OR(C26="",D26=""),"",C26&"-"&D26)
A27: =IF(B27="","",ROW()-6) | S27: =IF(OR(C27="",D27=""),"",C27&"-"&D27)
A28: =IF(B28="","",ROW()-6) | S28: =IF(OR(C28="",D28=""),"",C28&"-"&D28)
A29: =IF(B29="","",ROW()-6) | S29: =IF(OR(C29="",D29=""),"",C29&"-"&D29)
A30: =IF(B30="","",ROW()-6) | S30: =IF(OR(C30="",D30=""),"",C30&"-"&D30)
A31: =IF(B31="","",ROW()-6) | S31: =IF(OR(C31="",D31=""),"",C31&"-"&D31)
A32: =IF(B32="","",ROW()-6) | S32: =IF(OR(C32="",D32=""),"",C32&"-"&D32)
A33: =IF(B33="","",ROW()-6) | S33: =IF(OR(C33="",D33=""),"",C33&"-"&D33)
A34: =IF(B34="","",ROW()-6) | S34: =IF(OR(C34="",D34=""),"",C34&"-"&D34)
... A56: =IF(B56="","",ROW()-6) | S56: =IF(OR(C56="",D56=""),"",C56&"-"&D56)

Sheet Beschriftung
B1: Beschriftung Verteiler
B2: =IF(Anlage!B12="","Verteiler: –","Verteiler: "&Anlage!B12&IF(Anlage!D12="",""," · "&Anlage!D12))
B3: Mit 100 % drucken (keine Skalierung). Ein Feld = 1 TE = 17,5 mm – am Probedruck nachmessen. Inhalt kommt aus der Stromkreisliste (Reihe, Platz, BMK, Beschriftung kurz).
B5: Reihe 1
B6: =IFERROR(INDEX(Stromkreisliste!$B$7:$B$56,MATCH("1-1",Stromkreisliste!$S$7:$S$56,0))&CHAR(10)&INDEX(Stromkreisliste!$R$7:$R$56,MATCH("1-1",Stromkreisliste!$S$7:$S$56,0)),"") | C6: =IFERROR(INDEX(Stromkreisliste!$B$7:$B$56,MATCH("1-2",Stromkreisliste!$S$7:$S$56,0))&CHAR(10)&INDEX(Stromkreisliste!$R$7:$R$56,MATCH("1-2",Stromkreisliste!$S$7:$S$56,0)),"") | D6: =IFERROR(INDEX(Stromkreisliste!$B$7:$B$56,MATCH("1-3",Stromkreisliste!$S$7:$S$56,0))&CHAR(10)&INDEX(Stromkreisliste!$R$7:$R$56,MATCH("1-3",Stromkreisliste!$S$7:$S$56,0)),"") | E6: =IFERROR(INDEX(Stromkreisliste!$B$7:$B$56,MATCH("1-4",Stromkreisliste!$S$7:$S$56,0))&CHAR(10)&INDEX(Stromkreisliste!$R$7:$R$56,MATCH("1-4",Stromkreisliste!$S$7:$S$56,0)),"") | F6: =IFERROR(INDEX(Stromkreisliste!$B$7:$B$56,MATCH("1-5",Stromkreisliste!$S$7:$S$56,0))&CHAR(10)&INDEX(Stromkreisliste!$R$7:$R$56,MATCH("1-5",Stromkreisliste!$S$7:$S$56,0)),"") | G6: =IFERROR(INDEX(Stromkreisliste!$B$7:$B$56,MATCH("1-6",Stromkreisliste!$S$7:$S$56,0))&CHAR(10)&INDEX(Stromkreisliste!$R$7:$R$56,MATCH("1-6",Stromkreisliste!$S$7:$S$56,0)),"") | H6: =IFERROR(INDEX(Stromkreisliste!$B$7:$B$56,MATCH("1-7",Stromkreisliste!$S$7:$S$56,0))&CHAR(10)&INDEX(Stromkreisliste!$R$7:$R$56,MATCH("1-7",Stromkreisliste!$S$7:$S$56,0)),"") | I6: =IFERROR(INDEX(Stromkreisliste!$B$7:$B$56,MATCH("1-8",Stromkreisliste!$S$7:$S$56,0))&CHAR(10)&INDEX(Stromkreisliste!$R$7:$R$56,MATCH("1-8",Stromkreisliste!$S$7:$S$56,0)),"") | J6: =IFERROR(INDEX(Stromkreisliste!$B$7:$B$56,MATCH("1-9",Stromkreisliste!$S$7:$S$56,0))&CHAR(10)&INDEX(Stromkreisliste!$R$7:$R$56,MATCH("1-9",Stromkreisliste!$S$7:$S$56,0)),"") | K6: =IFERROR(INDEX(Stromkreisliste!$B$7:$B$56,MATCH("1-10",Stromkreisliste!$S$7:$S$56,0))&CHAR(10)&INDEX(Stromkreisliste!$R$7:$R$56,MATCH("1-10",Stromkreisliste!$S$7:$S$56,0)),"") | L6: =IFERROR(INDEX(Stromkreisliste!$B$7:$B$56,MATCH("1-11",Stromkreisliste!$S$7:$S$56,0))&CHAR(10)&INDEX(Stromkreisliste!$R$7:$R$56,MATCH("1-11",Stromkreisliste!$S$7:$S$56,0)),"") | M6: =IFERROR(INDEX(Stromkreisliste!$B$7:$B$56,MATCH("1-12",Stromkreisliste!$S$7:$S$56,0))&CHAR(10)&INDEX(Stromkreisliste!$R$7:$R$56,MATCH("1-12",Stromkreisliste!$S$7:$S$56,0)),"")
B8: Reihe 2
B9: =IFERROR(INDEX(Stromkreisliste!$B$7:$B$56,MATCH("2-1",Stromkreisliste!$S$7:$S$56,0))&CHAR(10)&INDEX(Stromkreisliste!$R$7:$R$56,MATCH("2-1",Stromkreisliste!$S$7:$S$56,0)),"") | C9: =IFERROR(INDEX(Stromkreisliste!$B$7:$B$56,MATCH("2-2",Stromkreisliste!$S$7:$S$56,0))&CHAR(10)&INDEX(Stromkreisliste!$R$7:$R$56,MATCH("2-2",Stromkreisliste!$S$7:$S$56,0)),"") | D9: =IFERROR(INDEX(Stromkreisliste!$B$7:$B$56,MATCH("2-3",Stromkreisliste!$S$7:$S$56,0))&CHAR(10)&INDEX(Stromkreisliste!$R$7:$R$56,MATCH("2-3",Stromkreisliste!$S$7:$S$56,0)),"") | E9: =IFERROR(INDEX(Stromkreisliste!$B$7:$B$56,MATCH("2-4",Stromkreisliste!$S$7:$S$56,0))&CHAR(10)&INDEX(Stromkreisliste!$R$7:$R$56,MATCH("2-4",Stromkreisliste!$S$7:$S$56,0)),"") | F9: =IFERROR(INDEX(Stromkreisliste!$B$7:$B$56,MATCH("2-5",Stromkreisliste!$S$7:$S$56,0))&CHAR(10)&INDEX(Stromkreisliste!$R$7:$R$56,MATCH("2-5",Stromkreisliste!$S$7:$S$56,0)),"") | G9: =IFERROR(INDEX(Stromkreisliste!$B$7:$B$56,MATCH("2-6",Stromkreisliste!$S$7:$S$56,0))&CHAR(10)&INDEX(Stromkreisliste!$R$7:$R$56,MATCH("2-6",Stromkreisliste!$S$7:$S$56,0)),"") | H9: =IFERROR(INDEX(Stromkreisliste!$B$7:$B$56,MATCH("2-7",Stromkreisliste!$S$7:$S$56,0))&CHAR(10)&INDEX(Stromkreisliste!$R$7:$R$56,MATCH("2-7",Stromkreisliste!$S$7:$S$56,0)),"") | I9: =IFERROR(INDEX(Stromkreisliste!$B$7:$B$56,MATCH("2-8",Stromkreisliste!$S$7:$S$56,0))&CHAR(10)&INDEX(Stromkreisliste!$R$7:$R$56,MATCH("2-8",Stromkreisliste!$S$7:$S$56,0)),"") | J9: =IFERROR(INDEX(Stromkreisliste!$B$7:$B$56,MATCH("2-9",Stromkreisliste!$S$7:$S$56,0))&CHAR(10)&INDEX(Stromkreisliste!$R$7:$R$56,MATCH("2-9",Stromkreisliste!$S$7:$S$56,0)),"") | K9: =IFERROR(INDEX(Stromkreisliste!$B$7:$B$56,MATCH("2-10",Stromkreisliste!$S$7:$S$56,0))&CHAR(10)&INDEX(Stromkreisliste!$R$7:$R$56,MATCH("2-10",Stromkreisliste!$S$7:$S$56,0)),"") | L9: =IFERROR(INDEX(Stromkreisliste!$B$7:$B$56,MATCH("2-11",Stromkreisliste!$S$7:$S$56,0))&CHAR(10)&INDEX(Stromkreisliste!$R$7:$R$56,MATCH("2-11",Stromkreisliste!$S$7:$S$56,0)),"") | M9: =IFERROR(INDEX(Stromkreisliste!$B$7:$B$56,MATCH("2-12",Stromkreisliste!$S$7:$S$56,0))&CHAR(10)&INDEX(Stromkreisliste!$R$7:$R$56,MATCH("2-12",Stromkreisliste!$S$7:$S$56,0)),"")
B11: Reihe 3
B12: =IFERROR(INDEX(Stromkreisliste!$B$7:$B$56,MATCH("3-1",Stromkreisliste!$S$7:$S$56,0))&CHAR(10)&INDEX(Stromkreisliste!$R$7:$R$56,MATCH("3-1",Stromkreisliste!$S$7:$S$56,0)),"") | C12: =IFERROR(INDEX(Stromkreisliste!$B$7:$B$56,MATCH("3-2",Stromkreisliste!$S$7:$S$56,0))&CHAR(10)&INDEX(Stromkreisliste!$R$7:$R$56,MATCH("3-2",Stromkreisliste!$S$7:$S$56,0)),"") | D12: =IFERROR(INDEX(Stromkreisliste!$B$7:$B$56,MATCH("3-3",Stromkreisliste!$S$7:$S$56,0))&CHAR(10)&INDEX(Stromkreisliste!$R$7:$R$56,MATCH("3-3",Stromkreisliste!$S$7:$S$56,0)),"") | E12: =IFERROR(INDEX(Stromkreisliste!$B$7:$B$56,MATCH("3-4",Stromkreisliste!$S$7:$S$56,0))&CHAR(10)&INDEX(Stromkreisliste!$R$7:$R$56,MATCH("3-4",Stromkreisliste!$S$7:$S$56,0)),"") | F12: =IFERROR(INDEX(Stromkreisliste!$B$7:$B$56,MATCH("3-5",Stromkreisliste!$S$7:$S$56,0))&CHAR(10)&INDEX(Stromkreisliste!$R$7:$R$56,MATCH("3-5",Stromkreisliste!$S$7:$S$56,0)),"") | G12: =IFERROR(INDEX(Stromkreisliste!$B$7:$B$56,MATCH("3-6",Stromkreisliste!$S$7:$S$56,0))&CHAR(10)&INDEX(Stromkreisliste!$R$7:$R$56,MATCH("3-6",Stromkreisliste!$S$7:$S$56,0)),"") | H12: =IFERROR(INDEX(Stromkreisliste!$B$7:$B$56,MATCH("3-7",Stromkreisliste!$S$7:$S$56,0))&CHAR(10)&INDEX(Stromkreisliste!$R$7:$R$56,MATCH("3-7",Stromkreisliste!$S$7:$S$56,0)),"") | I12: =IFERROR(INDEX(Stromkreisliste!$B$7:$B$56,MATCH("3-8",Stromkreisliste!$S$7:$S$56,0))&CHAR(10)&INDEX(Stromkreisliste!$R$7:$R$56,MATCH("3-8",Stromkreisliste!$S$7:$S$56,0)),"") | J12: =IFERROR(INDEX(Stromkreisliste!$B$7:$B$56,MATCH("3-9",Stromkreisliste!$S$7:$S$56,0))&CHAR(10)&INDEX(Stromkreisliste!$R$7:$R$56,MATCH("3-9",Stromkreisliste!$S$7:$S$56,0)),"") | K12: =IFERROR(INDEX(Stromkreisliste!$B$7:$B$56,MATCH("3-10",Stromkreisliste!$S$7:$S$56,0))&CHAR(10)&INDEX(Stromkreisliste!$R$7:$R$56,MATCH("3-10",Stromkreisliste!$S$7:$S$56,0)),"") | L12: =IFERROR(INDEX(Stromkreisliste!$B$7:$B$56,MATCH("3-11",Stromkreisliste!$S$7:$S$56,0))&CHAR(10)&INDEX(Stromkreisliste!$R$7:$R$56,MATCH("3-11",Stromkreisliste!$S$7:$S$56,0)),"") | M12: =IFERROR(INDEX(Stromkreisliste!$B$7:$B$56,MATCH("3-12",Stromkreisliste!$S$7:$S$56,0))&CHAR(10)&INDEX(Stromkreisliste!$R$7:$R$56,MATCH("3-12",Stromkreisliste!$S$7:$S$56,0)),"")
B14: Reihe 4
B15: =IFERROR(INDEX(Stromkreisliste!$B$7:$B$56,MATCH("4-1",Stromkreisliste!$S$7:$S$56,0))&CHAR(10)&INDEX(Stromkreisliste!$R$7:$R$56,MATCH("4-1",Stromkreisliste!$S$7:$S$56,0)),"") | C15: =IFERROR(INDEX(Stromkreisliste!$B$7:$B$56,MATCH("4-2",Stromkreisliste!$S$7:$S$56,0))&CHAR(10)&INDEX(Stromkreisliste!$R$7:$R$56,MATCH("4-2",Stromkreisliste!$S$7:$S$56,0)),"") | D15: =IFERROR(INDEX(Stromkreisliste!$B$7:$B$56,MATCH("4-3",Stromkreisliste!$S$7:$S$56,0))&CHAR(10)&INDEX(Stromkreisliste!$R$7:$R$56,MATCH("4-3",Stromkreisliste!$S$7:$S$56,0)),"") | E15: =IFERROR(INDEX(Stromkreisliste!$B$7:$B$56,MATCH("4-4",Stromkreisliste!$S$7:$S$56,0))&CHAR(10)&INDEX(Stromkreisliste!$R$7:$R$56,MATCH("4-4",Stromkreisliste!$S$7:$S$56,0)),"") | F15: =IFERROR(INDEX(Stromkreisliste!$B$7:$B$56,MATCH("4-5",Stromkreisliste!$S$7:$S$56,0))&CHAR(10)&INDEX(Stromkreisliste!$R$7:$R$56,MATCH("4-5",Stromkreisliste!$S$7:$S$56,0)),"") | G15: =IFERROR(INDEX(Stromkreisliste!$B$7:$B$56,MATCH("4-6",Stromkreisliste!$S$7:$S$56,0))&CHAR(10)&INDEX(Stromkreisliste!$R$7:$R$56,MATCH("4-6",Stromkreisliste!$S$7:$S$56,0)),"") | H15: =IFERROR(INDEX(Stromkreisliste!$B$7:$B$56,MATCH("4-7",Stromkreisliste!$S$7:$S$56,0))&CHAR(10)&INDEX(Stromkreisliste!$R$7:$R$56,MATCH("4-7",Stromkreisliste!$S$7:$S$56,0)),"") | I15: =IFERROR(INDEX(Stromkreisliste!$B$7:$B$56,MATCH("4-8",Stromkreisliste!$S$7:$S$56,0))&CHAR(10)&INDEX(Stromkreisliste!$R$7:$R$56,MATCH("4-8",Stromkreisliste!$S$7:$S$56,0)),"") | J15: =IFERROR(INDEX(Stromkreisliste!$B$7:$B$56,MATCH("4-9",Stromkreisliste!$S$7:$S$56,0))&CHAR(10)&INDEX(Stromkreisliste!$R$7:$R$56,MATCH("4-9",Stromkreisliste!$S$7:$S$56,0)),"") | K15: =IFERROR(INDEX(Stromkreisliste!$B$7:$B$56,MATCH("4-10",Stromkreisliste!$S$7:$S$56,0))&CHAR(10)&INDEX(Stromkreisliste!$R$7:$R$56,MATCH("4-10",Stromkreisliste!$S$7:$S$56,0)),"") | L15: =IFERROR(INDEX(Stromkreisliste!$B$7:$B$56,MATCH("4-11",Stromkreisliste!$S$7:$S$56,0))&CHAR(10)&INDEX(Stromkreisliste!$R$7:$R$56,MATCH("4-11",Stromkreisliste!$S$7:$S$56,0)),"") | M15: =IFERROR(INDEX(Stromkreisliste!$B$7:$B$56,MATCH("4-12",Stromkreisliste!$S$7:$S$56,0))&CHAR(10)&INDEX(Stromkreisliste!$R$7:$R$56,MATCH("4-12",Stromkreisliste!$S$7:$S$56,0)),"")
B17: Reihe 5
B18: =IFERROR(INDEX(Stromkreisliste!$B$7:$B$56,MATCH("5-1",Stromkreisliste!$S$7:$S$56,0))&CHAR(10)&INDEX(Stromkreisliste!$R$7:$R$56,MATCH("5-1",Stromkreisliste!$S$7:$S$56,0)),"") | C18: =IFERROR(INDEX(Stromkreisliste!$B$7:$B$56,MATCH("5-2",Stromkreisliste!$S$7:$S$56,0))&CHAR(10)&INDEX(Stromkreisliste!$R$7:$R$56,MATCH("5-2",Stromkreisliste!$S$7:$S$56,0)),"") | D18: =IFERROR(INDEX(Stromkreisliste!$B$7:$B$56,MATCH("5-3",Stromkreisliste!$S$7:$S$56,0))&CHAR(10)&INDEX(Stromkreisliste!$R$7:$R$56,MATCH("5-3",Stromkreisliste!$S$7:$S$56,0)),"") | E18: =IFERROR(INDEX(Stromkreisliste!$B$7:$B$56,MATCH("5-4",Stromkreisliste!$S$7:$S$56,0))&CHAR(10)&INDEX(Stromkreisliste!$R$7:$R$56,MATCH("5-4",Stromkreisliste!$S$7:$S$56,0)),"") | F18: =IFERROR(INDEX(Stromkreisliste!$B$7:$B$56,MATCH("5-5",Stromkreisliste!$S$7:$S$56,0))&CHAR(10)&INDEX(Stromkreisliste!$R$7:$R$56,MATCH("5-5",Stromkreisliste!$S$7:$S$56,0)),"") | G18: =IFERROR(INDEX(Stromkreisliste!$B$7:$B$56,MATCH("5-6",Stromkreisliste!$S$7:$S$56,0))&CHAR(10)&INDEX(Stromkreisliste!$R$7:$R$56,MATCH("5-6",Stromkreisliste!$S$7:$S$56,0)),"") | H18: =IFERROR(INDEX(Stromkreisliste!$B$7:$B$56,MATCH("5-7",Stromkreisliste!$S$7:$S$56,0))&CHAR(10)&INDEX(Stromkreisliste!$R$7:$R$56,MATCH("5-7",Stromkreisliste!$S$7:$S$56,0)),"") | I18: =IFERROR(INDEX(Stromkreisliste!$B$7:$B$56,MATCH("5-8",Stromkreisliste!$S$7:$S$56,0))&CHAR(10)&INDEX(Stromkreisliste!$R$7:$R$56,MATCH("5-8",Stromkreisliste!$S$7:$S$56,0)),"") | J18: =IFERROR(INDEX(Stromkreisliste!$B$7:$B$56,MATCH("5-9",Stromkreisliste!$S$7:$S$56,0))&CHAR(10)&INDEX(Stromkreisliste!$R$7:$R$56,MATCH("5-9",Stromkreisliste!$S$7:$S$56,0)),"") | K18: =IFERROR(INDEX(Stromkreisliste!$B$7:$B$56,MATCH("5-10",Stromkreisliste!$S$7:$S$56,0))&CHAR(10)&INDEX(Stromkreisliste!$R$7:$R$56,MATCH("5-10",Stromkreisliste!$S$7:$S$56,0)),"") | L18: =IFERROR(INDEX(Stromkreisliste!$B$7:$B$56,MATCH("5-11",Stromkreisliste!$S$7:$S$56,0))&CHAR(10)&INDEX(Stromkreisliste!$R$7:$R$56,MATCH("5-11",Stromkreisliste!$S$7:$S$56,0)),"") | M18: =IFERROR(INDEX(Stromkreisliste!$B$7:$B$56,MATCH("5-12",Stromkreisliste!$S$7:$S$56,0))&CHAR(10)&INDEX(Stromkreisliste!$R$7:$R$56,MATCH("5-12",Stromkreisliste!$S$7:$S$56,0)),"")
B20: Reihe 6
B21: =IFERROR(INDEX(Stromkreisliste!$B$7:$B$56,MATCH("6-1",Stromkreisliste!$S$7:$S$56,0))&CHAR(10)&INDEX(Stromkreisliste!$R$7:$R$56,MATCH("6-1",Stromkreisliste!$S$7:$S$56,0)),"") | C21: =IFERROR(INDEX(Stromkreisliste!$B$7:$B$56,MATCH("6-2",Stromkreisliste!$S$7:$S$56,0))&CHAR(10)&INDEX(Stromkreisliste!$R$7:$R$56,MATCH("6-2",Stromkreisliste!$S$7:$S$56,0)),"") | D21: =IFERROR(INDEX(Stromkreisliste!$B$7:$B$56,MATCH("6-3",Stromkreisliste!$S$7:$S$56,0))&CHAR(10)&INDEX(Stromkreisliste!$R$7:$R$56,MATCH("6-3",Stromkreisliste!$S$7:$S$56,0)),"") | E21: =IFERROR(INDEX(Stromkreisliste!$B$7:$B$56,MATCH("6-4",Stromkreisliste!$S$7:$S$56,0))&CHAR(10)&INDEX(Stromkreisliste!$R$7:$R$56,MATCH("6-4",Stromkreisliste!$S$7:$S$56,0)),"") | F21: =IFERROR(INDEX(Stromkreisliste!$B$7:$B$56,MATCH("6-5",Stromkreisliste!$S$7:$S$56,0))&CHAR(10)&INDEX(Stromkreisliste!$R$7:$R$56,MATCH("6-5",Stromkreisliste!$S$7:$S$56,0)),"") | G21: =IFERROR(INDEX(Stromkreisliste!$B$7:$B$56,MATCH("6-6",Stromkreisliste!$S$7:$S$56,0))&CHAR(10)&INDEX(Stromkreisliste!$R$7:$R$56,MATCH("6-6",Stromkreisliste!$S$7:$S$56,0)),"") | H21: =IFERROR(INDEX(Stromkreisliste!$B$7:$B$56,MATCH("6-7",Stromkreisliste!$S$7:$S$56,0))&CHAR(10)&INDEX(Stromkreisliste!$R$7:$R$56,MATCH("6-7",Stromkreisliste!$S$7:$S$56,0)),"") | I21: =IFERROR(INDEX(Stromkreisliste!$B$7:$B$56,MATCH("6-8",Stromkreisliste!$S$7:$S$56,0))&CHAR(10)&INDEX(Stromkreisliste!$R$7:$R$56,MATCH("6-8",Stromkreisliste!$S$7:$S$56,0)),"") | J21: =IFERROR(INDEX(Stromkreisliste!$B$7:$B$56,MATCH("6-9",Stromkreisliste!$S$7:$S$56,0))&CHAR(10)&INDEX(Stromkreisliste!$R$7:$R$56,MATCH("6-9",Stromkreisliste!$S$7:$S$56,0)),"") | K21: =IFERROR(INDEX(Stromkreisliste!$B$7:$B$56,MATCH("6-10",Stromkreisliste!$S$7:$S$56,0))&CHAR(10)&INDEX(Stromkreisliste!$R$7:$R$56,MATCH("6-10",Stromkreisliste!$S$7:$S$56,0)),"") | L21: =IFERROR(INDEX(Stromkreisliste!$B$7:$B$56,MATCH("6-11",Stromkreisliste!$S$7:$S$56,0))&CHAR(10)&INDEX(Stromkreisliste!$R$7:$R$56,MATCH("6-11",Stromkreisliste!$S$7:$S$56,0)),"") | M21: =IFERROR(INDEX(Stromkreisliste!$B$7:$B$56,MATCH("6-12",Stromkreisliste!$S$7:$S$56,0))&CHAR(10)&INDEX(Stromkreisliste!$R$7:$R$56,MATCH("6-12",Stromkreisliste!$S$7:$S$56,0)),"")
B23: Reihe 7
B24: =IFERROR(INDEX(Stromkreisliste!$B$7:$B$56,MATCH("7-1",Stromkreisliste!$S$7:$S$56,0))&CHAR(10)&INDEX(Stromkreisliste!$R$7:$R$56,MATCH("7-1",Stromkreisliste!$S$7:$S$56,0)),"") | C24: =IFERROR(INDEX(Stromkreisliste!$B$7:$B$56,MATCH("7-2",Stromkreisliste!$S$7:$S$56,0))&CHAR(10)&INDEX(Stromkreisliste!$R$7:$R$56,MATCH("7-2",Stromkreisliste!$S$7:$S$56,0)),"") | D24: =IFERROR(INDEX(Stromkreisliste!$B$7:$B$56,MATCH("7-3",Stromkreisliste!$S$7:$S$56,0))&CHAR(10)&INDEX(Stromkreisliste!$R$7:$R$56,MATCH("7-3",Stromkreisliste!$S$7:$S$56,0)),"") | E24: =IFERROR(INDEX(Stromkreisliste!$B$7:$B$56,MATCH("7-4",Stromkreisliste!$S$7:$S$56,0))&CHAR(10)&INDEX(Stromkreisliste!$R$7:$R$56,MATCH("7-4",Stromkreisliste!$S$7:$S$56,0)),"") | F24: =IFERROR(INDEX(Stromkreisliste!$B$7:$B$56,MATCH("7-5",Stromkreisliste!$S$7:$S$56,0))&CHAR(10)&INDEX(Stromkreisliste!$R$7:$R$56,MATCH("7-5",Stromkreisliste!$S$7:$S$56,0)),"") | G24: =IFERROR(INDEX(Stromkreisliste!$B$7:$B$56,MATCH("7-6",Stromkreisliste!$S$7:$S$56,0))&CHAR(10)&INDEX(Stromkreisliste!$R$7:$R$56,MATCH("7-6",Stromkreisliste!$S$7:$S$56,0)),"") | H24: =IFERROR(INDEX(Stromkreisliste!$B$7:$B$56,MATCH("7-7",Stromkreisliste!$S$7:$S$56,0))&CHAR(10)&INDEX(Stromkreisliste!$R$7:$R$56,MATCH("7-7",Stromkreisliste!$S$7:$S$56,0)),"") | I24: =IFERROR(INDEX(Stromkreisliste!$B$7:$B$56,MATCH("7-8",Stromkreisliste!$S$7:$S$56,0))&CHAR(10)&INDEX(Stromkreisliste!$R$7:$R$56,MATCH("7-8",Stromkreisliste!$S$7:$S$56,0)),"") | J24: =IFERROR(INDEX(Stromkreisliste!$B$7:$B$56,MATCH("7-9",Stromkreisliste!$S$7:$S$56,0))&CHAR(10)&INDEX(Stromkreisliste!$R$7:$R$56,MATCH("7-9",Stromkreisliste!$S$7:$S$56,0)),"") | K24: =IFERROR(INDEX(Stromkreisliste!$B$7:$B$56,MATCH("7-10",Stromkreisliste!$S$7:$S$56,0))&CHAR(10)&INDEX(Stromkreisliste!$R$7:$R$56,MATCH("7-10",Stromkreisliste!$S$7:$S$56,0)),"") | L24: =IFERROR(INDEX(Stromkreisliste!$B$7:$B$56,MATCH("7-11",Stromkreisliste!$S$7:$S$56,0))&CHAR(10)&INDEX(Stromkreisliste!$R$7:$R$56,MATCH("7-11",Stromkreisliste!$S$7:$S$56,0)),"") | M24: =IFERROR(INDEX(Stromkreisliste!$B$7:$B$56,MATCH("7-12",Stromkreisliste!$S$7:$S$56,0))&CHAR(10)&INDEX(Stromkreisliste!$R$7:$R$56,MATCH("7-12",Stromkreisliste!$S$7:$S$56,0)),"")
B26: Reihe 8
B27: =IFERROR(INDEX(Stromkreisliste!$B$7:$B$56,MATCH("8-1",Stromkreisliste!$S$7:$S$56,0))&CHAR(10)&INDEX(Stromkreisliste!$R$7:$R$56,MATCH("8-1",Stromkreisliste!$S$7:$S$56,0)),"") | C27: =IFERROR(INDEX(Stromkreisliste!$B$7:$B$56,MATCH("8-2",Stromkreisliste!$S$7:$S$56,0))&CHAR(10)&INDEX(Stromkreisliste!$R$7:$R$56,MATCH("8-2",Stromkreisliste!$S$7:$S$56,0)),"") | D27: =IFERROR(INDEX(Stromkreisliste!$B$7:$B$56,MATCH("8-3",Stromkreisliste!$S$7:$S$56,0))&CHAR(10)&INDEX(Stromkreisliste!$R$7:$R$56,MATCH("8-3",Stromkreisliste!$S$7:$S$56,0)),"") | E27: =IFERROR(INDEX(Stromkreisliste!$B$7:$B$56,MATCH("8-4",Stromkreisliste!$S$7:$S$56,0))&CHAR(10)&INDEX(Stromkreisliste!$R$7:$R$56,MATCH("8-4",Stromkreisliste!$S$7:$S$56,0)),"") | F27: =IFERROR(INDEX(Stromkreisliste!$B$7:$B$56,MATCH("8-5",Stromkreisliste!$S$7:$S$56,0))&CHAR(10)&INDEX(Stromkreisliste!$R$7:$R$56,MATCH("8-5",Stromkreisliste!$S$7:$S$56,0)),"") | G27: =IFERROR(INDEX(Stromkreisliste!$B$7:$B$56,MATCH("8-6",Stromkreisliste!$S$7:$S$56,0))&CHAR(10)&INDEX(Stromkreisliste!$R$7:$R$56,MATCH("8-6",Stromkreisliste!$S$7:$S$56,0)),"") | H27: =IFERROR(INDEX(Stromkreisliste!$B$7:$B$56,MATCH("8-7",Stromkreisliste!$S$7:$S$56,0))&CHAR(10)&INDEX(Stromkreisliste!$R$7:$R$56,MATCH("8-7",Stromkreisliste!$S$7:$S$56,0)),"") | I27: =IFERROR(INDEX(Stromkreisliste!$B$7:$B$56,MATCH("8-8",Stromkreisliste!$S$7:$S$56,0))&CHAR(10)&INDEX(Stromkreisliste!$R$7:$R$56,MATCH("8-8",Stromkreisliste!$S$7:$S$56,0)),"") | J27: =IFERROR(INDEX(Stromkreisliste!$B$7:$B$56,MATCH("8-9",Stromkreisliste!$S$7:$S$56,0))&CHAR(10)&INDEX(Stromkreisliste!$R$7:$R$56,MATCH("8-9",Stromkreisliste!$S$7:$S$56,0)),"") | K27: =IFERROR(INDEX(Stromkreisliste!$B$7:$B$56,MATCH("8-10",Stromkreisliste!$S$7:$S$56,0))&CHAR(10)&INDEX(Stromkreisliste!$R$7:$R$56,MATCH("8-10",Stromkreisliste!$S$7:$S$56,0)),"") | L27: =IFERROR(INDEX(Stromkreisliste!$B$7:$B$56,MATCH("8-11",Stromkreisliste!$S$7:$S$56,0))&CHAR(10)&INDEX(Stromkreisliste!$R$7:$R$56,MATCH("8-11",Stromkreisliste!$S$7:$S$56,0)),"") | M27: =IFERROR(INDEX(Stromkreisliste!$B$7:$B$56,MATCH("8-12",Stromkreisliste!$S$7:$S$56,0))&CHAR(10)&INDEX(Stromkreisliste!$R$7:$R$56,MATCH("8-12",Stromkreisliste!$S$7:$S$56,0)),"")

Sheet Prüfbericht
A1: Prüfbericht
A2: Prüfung elektrischer Anlagen nach DIN VDE 0100-600 bzw. DIN VDE 0105-100
A5: ANLAGE
A6: Auftraggeber / Betreiber | B6: =IF(Anlage!B7="","",Anlage!B7) | C6: Auftrags-Nr. | D6: =IF(Anlage!B9="","",Anlage!B9)
A7: Anlagenanschrift | B7: =IF(Anlage!B8="","",Anlage!B8)
A8: Verteiler | B8: =IF(Anlage!B12="","",Anlage!B12) | C8: Standort | D8: =IF(Anlage!D12="","",Anlage!D12)
A9: Netzsystem | B9: =IF(Anlage!B18="","",Anlage!B18) | C9: Nennspannung | D9: =IF(Anlage!D18="","",Anlage!D18)
A11: PRÜFUNG
A12: Prüfart
A13: Prüfdatum | C13: Prüfer | D13: =IF(Anlage!B26="","",Anlage!B26)
A14: Messgerät (Hersteller, Typ) | C14: Seriennummer
A15: Kalibriert bis | C15: Erdungswiderst. RA | D15: =IF(Anlage!D20="","",Anlage!D20&" Ω")
A17: 1 Besichtigen | C17: Ergebnis | D17: Bemerkung
A18: Auswahl der Betriebsmittel passend zu den äußeren Einflüssen (Schutzart, Brandschutz)
A19: Basisschutz: Abdeckungen, Isolierungen und Gehäuse vollständig und unbeschädigt
A20: Leiterquerschnitte und Schutzeinrichtungen richtig zugeordnet
A21: Kennzeichnung von Stromkreisen, Schutzeinrichtungen und Leitern (N blau, PE grün-gelb)
A22: Verteiler zugänglich, Bedienung und Beschriftung in Ordnung
A23: Leitungsverlegung, Befestigung und mechanischer Schutz
A24: Klemmstellen fest, Leiterverbindungen fachgerecht
A25: Schutzpotentialausgleich (Haupt- und zusätzlicher) vorhanden und angeschlossen
A26: Brandabschottungen bei Durchführungen
A27: Zusätzlicher Schutz durch RCD ≤ 30 mA, wo gefordert (Steckdosen ≤ 32 A, Beleuchtung in Wohnungen, außen)
A28: Überspannungsschutz, wo gefordert
A29: Dokumentation vorhanden (Stromkreisliste, Pläne)
A30: 2 Erproben | C30: Ergebnis | D30: Bemerkung
A31: Funktion der Fehlerstrom-Schutzeinrichtungen (Prüftaste)
A32: Funktion von Schalt-, Steuer- und Verriegelungseinrichtungen
A33: Hauptschalter / Not-Aus
A34: Funktion von Beleuchtung und Steckdosen (Stichprobe)
A35: 3 Messen – Werte siehe Messprotokoll | C35: Ergebnis | D35: Bemerkung
A36: Durchgängigkeit der Schutzleiter und des Potentialausgleichs (RPE)
A37: Isolationswiderstand (Riso) | C37: =IF(COUNT(Messprotokoll!$F$7:$G$56)=0,"",IF(SUM(Messprotokoll!$R$7:$R$56)>0,"n.i.O.","i.O.")) | D37: =IF(COUNT(Messprotokoll!$F$7:$F$56)=0,"",COUNT(Messprotokoll!$F$7:$F$56)&" Stromkreise gemessen")
A38: Schleifenimpedanz / Abschaltbedingung (Zs) | C38: =IF(COUNT(Messprotokoll!$I$7:$I$56)=0,"",IF(SUM(Messprotokoll!$S$7:$S$56)>0,"n.i.O.","i.O.")) | D38: =IF(COUNT(Messprotokoll!$I$7:$I$56)=0,"",COUNT(Messprotokoll!$I$7:$I$56)&" Stromkreise gemessen")
A39: Fehlerstrom-Schutzeinrichtungen (IΔ, tA, UB) | C39: =IF(COUNT(Messprotokoll!$L$7:$N$56)=0,"",IF(SUM(Messprotokoll!$T$7:$T$56)>0,"n.i.O.","i.O.")) | D39: =IF(COUNT(Messprotokoll!$M$7:$M$56)=0,"",COUNT(Messprotokoll!$M$7:$M$56)&" FI gemessen")
A40: Drehfeld der Drehstromsteckdosen | C40: =IF(COUNTA(Messprotokoll!$O$7:$O$56)=0,"",IF(SUM(Messprotokoll!$U$7:$U$56)>0,"n.i.O.","i.O."))
A41: Erdungswiderstand (bei TT-System)
A43: MÄNGEL UND HINWEISE
A49: ERGEBNIS
A50: Gesamtergebnis
...

Sheet Messprotokoll
A1: Messprotokoll
A2: Messwerte je Stromkreis · Muster Elektrotechnik GmbH
A4: Verteiler | C4: =IF(Anlage!B12="","",Anlage!B12&IF(Anlage!D12="",""," · "&Anlage!D12)) | D4: Objekt | E4: =IF(Anlage!B8="","",Anlage!B8) | K4: Datum | M4: =IF('Prüfbericht'!B13="","",'Prüfbericht'!B13) | O4: Gerät | P4: =IF('Prüfbericht'!B14="","",'Prüfbericht'!B14)
A5: Grenzwerte | C5: Nennspannung U0 (V) | D5: 230 | E5: Riso min (MΩ) | F5: 1 | G5: Faktor Zs | H5: =2/3 | I5: tA max (ms) | J5: 300 | K5: UB max (V) | L5: 50 | M5: Zs max = Faktor × U0 / Ia · Ia: B = 5·In, C = 10·In, D = 20·In, K = 14·In, Z = 3·In. Bewertung ist eine Hilfe – maßgeblich sind Norm und Herstellerangaben.
A6: Nr. | B6: BMK | C6: Stromkreis / Verbraucher | D6: Schutzorgan | E6: Leitung | F6: Riso L–PE (MΩ) | G6: Riso N–PE (MΩ) | H6: RPE (Ω) | I6: Zs L–PE (Ω) | J6: Ik (A) | K6: Zs max (Ω) | L6: IΔ (mA) | M6: tA (ms) | N6: UB (V) | O6: Dreh-feld | P6: Ergebnis | Q6: Bemerkung | R6: Riso | S6: Zs | T6: FI | U6: Dreh
A7: =IF(Stromkreisliste!B7="","",ROW()-6) | B7: =IF(Stromkreisliste!B7="","",Stromkreisliste!B7) | C7: =IF(Stromkreisliste!B7="","",Stromkreisliste!P7&IF(AND(Stromkreisliste!P7<>"",Stromkreisliste!Q7<>"")," – ","")&Stromkreisliste!Q7) | D7: =IF(Stromkreisliste!B7="","",IF(Stromkreisliste!F7="FI/RCD","FI "&Stromkreisliste!H7&" A / "&Stromkreisliste!K7&" mA",IF(Stromkreisliste!F7="FI/LS (RCBO)","FI/LS "&Stromkreisliste!G7&Stromkreisliste!H7&" / "&Stromkreisliste!K7&" mA",IF(Stromkreisliste!G7="",Stromkreisliste!F7&IF(Stromkreisliste!H7="",""," "&Stromkreisliste!H7&" A"),Stromkreisliste!G7&Stromkreisliste!H7)))) | E7: =IF(Stromkreisliste!B7="","",TRIM(Stromkreisliste!M7&" "&Stromkreisliste!N7)) | J7: =IF(N(I7)>0,$D$5/I7,"") | K7: =IF(OR(Stromkreisliste!B7="",N(Stromkreisliste!H7)=0),"",IFERROR($H$5*$D$5/(Stromkreisliste!H7*INDEX({5,10,20,14,3},MATCH(Stromkreisliste!G7,{"B","C","D","K","Z"},0))),"")) | P7: =IF(COUNTA(F7:I7,L7:O7)=0,"",IF(R7+S7+T7+U7>0,"n.i.O.","i.O.")) | R7: =IF(OR(AND(ISNUMBER(F7),F7<$F$5),AND(ISNUMBER(G7),G7<$F$5)),1,0) | S7: =IF(AND(ISNUMBER(I7),N(K7)>0,I7>N(K7)),1,0) | T7: =IF(OR(AND(ISNUMBER(L7),N(Stromkreisliste!K7)>0,OR(L7>N(Stromkreisliste!K7),L7<0.5*N(Stromkreisliste!K7))),AND(ISNUMBER(M7),M7>$J$5),AND(ISNUMBER(N7),N7>$L$5)),1,0) | U7: =IF(O7="links",1,0)
A8: =IF(Stromkreisliste!B8="","",ROW()-6) | B8: =IF(Stromkreisliste!B8="","",Stromkreisliste!B8) | C8: =IF(Stromkreisliste!B8="","",Stromkreisliste!P8&IF(AND(Stromkreisliste!P8<>"",Stromkreisliste!Q8<>"")," – ","")&Stromkreisliste!Q8) | D8: =IF(Stromkreisliste!B8="","",IF(Stromkreisliste!F8="FI/RCD","FI "&Stromkreisliste!H8&" A / "&Stromkreisliste!K8&" mA",IF(Stromkreisliste!F8="FI/LS (RCBO)","FI/LS "&Stromkreisliste!G8&Stromkreisliste!H8&" / "&Stromkreisliste!K8&" mA",IF(Stromkreisliste!G8="",Stromkreisliste!F8&IF(Stromkreisliste!H8="",""," "&Stromkreisliste!H8&" A"),Stromkreisliste!G8&Stromkreisliste!H8)))) | E8: =IF(Stromkreisliste!B8="","",TRIM(Stromkreisliste!M8&" "&Stromkreisliste!N8)) | J8: =IF(N(I8)>0,$D$5/I8,"") | K8: =IF(OR(Stromkreisliste!B8="",N(Stromkreisliste!H8)=0),"",IFERROR($H$5*$D$5/(Stromkreisliste!H8*INDEX({5,10,20,14,3},MATCH(Stromkreisliste!G8,{"B","C","D","K","Z"},0))),"")) | P8: =IF(COUNTA(F8:I8,L8:O8)=0,"",IF(R8+S8+T8+U8>0,"n.i.O.","i.O.")) | R8: =IF(OR(AND(ISNUMBER(F8),F8<$F$5),AND(ISNUMBER(G8),G8<$F$5)),1,0) | S8: =IF(AND(ISNUMBER(I8),N(K8)>0,I8>N(K8)),1,0) | T8: =IF(OR(AND(ISNUMBER(L8),N(Stromkreisliste!K8)>0,OR(L8>N(Stromkreisliste!K8),L8<0.5*N(Stromkreisliste!K8))),AND(ISNUMBER(M8),M8>$J$5),AND(ISNUMBER(N8),N8>$L$5)),1,0) | U8: =IF(O8="links",1,0)
A9: =IF(Stromkreisliste!B9="","",ROW()-6) | B9: =IF(Stromkreisliste!B9="","",Stromkreisliste!B9) | C9: =IF(Stromkreisliste!B9="","",Stromkreisliste!P9&IF(AND(Stromkreisliste!P9<>"",Stromkreisliste!Q9<>"")," – ","")&Stromkreisliste!Q9) | D9: =IF(Stromkreisliste!B9="","",IF(Stromkreisliste!F9="FI/RCD","FI "&Stromkreisliste!H9&" A / "&Stromkreisliste!K9&" mA",IF(Stromkreisliste!F9="FI/LS (RCBO)","FI/LS "&Stromkreisliste!G9&Stromkreisliste!H9&" / "&Stromkreisliste!K9&" mA",IF(Stromkreisliste!G9="",Stromkreisliste!F9&IF(Stromkreisliste!H9="",""," "&Stromkreisliste!H9&" A"),Stromkreisliste!G9&Stromkreisliste!H9)))) | E9: =IF(Stromkreisliste!B9="","",TRIM(Stromkreisliste!M9&" "&Stromkreisliste!N9)) | J9: =IF(N(I9)>0,$D$5/I9,"") | K9: =IF(OR(Stromkreisliste!B9="",N(Stromkreisliste!H9)=0),"",IFERROR($H$5*$D$5/(Stromkreisliste!H9*INDEX({5,10,20,14,3},MATCH(Stromkreisliste!G9,{"B","C","D","K","Z"},0))),"")) | P9: =IF(COUNTA(F9:I9,L9:O9)=0,"",IF(R9+S9+T9+U9>0,"n.i.O.","i.O.")) | R9: =IF(OR(AND(ISNUMBER(F9),F9<$F$5),AND(ISNUMBER(G9),G9<$F$5)),1,0) | S9: =IF(AND(ISNUMBER(I9),N(K9)>0,I9>N(K9)),1,0) | T9: =IF(OR(AND(ISNUMBER(L9),N(Stromkreisliste!K9)>0,OR(L9>N(Stromkreisliste!K9),L9<0.5*N(Stromkreisliste!K9))),AND(ISNUMBER(M9),M9>$J$5),AND(ISNUMBER(N9),N9>$L$5)),1,0) | U9: =IF(O9="links",1,0)
A10: =IF(Stromkreisliste!B10="","",ROW()-6) | B10: =IF(Stromkreisliste!B10="","",Stromkreisliste!B10) | C10: =IF(Stromkreisliste!B10="","",Stromkreisliste!P10&IF(AND(Stromkreisliste!P10<>"",Stromkreisliste!Q10<>"")," – ","")&Stromkreisliste!Q10) | D10: =IF(Stromkreisliste!B10="","",IF(Stromkreisliste!F10="FI/RCD","FI "&Stromkreisliste!H10&" A / "&Stromkreisliste!K10&" mA",IF(Stromkreisliste!F10="FI/LS (RCBO)","FI/LS "&Stromkreisliste!G10&Stromkreisliste!H10&" / "&Stromkreisliste!K10&" mA",IF(Stromkreisliste!G10="",Stromkreisliste!F10&IF(Stromkreisliste!H10="",""," "&Stromkreisliste!H10&" A"),Stromkreisliste!G10&Stromkreisliste!H10)))) | E10: =IF(Stromkreisliste!B10="","",TRIM(Stromkreisliste!M10&" "&Stromkreisliste!N10)) | J10: =IF(N(I10)>0,$D$5/I10,"") | K10: =IF(OR(Stromkreisliste!B10="",N(Stromkreisliste!H10)=0),"",IFERROR($H$5*$D$5/(Stromkreisliste!H10*INDEX({5,10,20,14,3},MATCH(Stromkreisliste!G10,{"B","C","D","K","Z"},0))),"")) | P10: =IF(COUNTA(F10:I10,L10:O10)=0,"",IF(R10+S10+T10+U10>0,"n.i.O.","i.O.")) | R10: =IF(OR(AND(ISNUMBER(F10),F10<$F$5),AND(ISNUMBER(G10),G10<$F$5)),1,0) | S10: =IF(AND(ISNUMBER(I10),N(K10)>0,I10>N(K10)),1,0) | T10: =IF(OR(AND(ISNUMBER(L10),N(Stromkreisliste!K10)>0,OR(L10>N(Stromkreisliste!K10),L10<0.5*N(Stromkreisliste!K10))),AND(ISNUMBER(M10),M10>$J$5),AND(ISNUMBER(N10),N10>$L$5)),1,0) | U10: =IF(O10="links",1,0)
A11: =IF(Stromkreisliste!B11="","",ROW()-6) | B11: =IF(Stromkreisliste!B11="","",Stromkreisliste!B11) | C11: =IF(Stromkreisliste!B11="","",Stromkreisliste!P11&IF(AND(Stromkreisliste!P11<>"",Stromkreisliste!Q11<>"")," – ","")&Stromkreisliste!Q11) | D11: =IF(Stromkreisliste!B11="","",IF(Stromkreisliste!F11="FI/RCD","FI "&Stromkreisliste!H11&" A / "&Stromkreisliste!K11&" mA",IF(Stromkreisliste!F11="FI/LS (RCBO)","FI/LS "&Stromkreisliste!G11&Stromkreisliste!H11&" / "&Stromkreisliste!K11&" mA",IF(Stromkreisliste!G11="",Stromkreisliste!F11&IF(Stromkreisliste!H11="",""," "&Stromkreisliste!H11&" A"),Stromkreisliste!G11&Stromkreisliste!H11)))) | E11: =IF(Stromkreisliste!B11="","",TRIM(Stromkreisliste!M11&" "&Stromkreisliste!N11)) | J11: =IF(N(I11)>0,$D$5/I11,"") | K11: =IF(OR(Stromkreisliste!B11="",N(Stromkreisliste!H11)=0),"",IFERROR($H$5*$D$5/(Stromkreisliste!H11*INDEX({5,10,20,14,3},MATCH(Stromkreisliste!G11,{"B","C","D","K","Z"},0))),"")) | P11: =IF(COUNTA(F11:I11,L11:O11)=0,"",IF(R11+S11+T11+U11>0,"n.i.O.","i.O.")) | R11: =IF(OR(AND(ISNUMBER(F11),F11<$F$5),AND(ISNUMBER(G11),G11<$F$5)),1,0) | S11: =IF(AND(ISNUMBER(I11),N(K11)>0,I11>N(K11)),1,0) | T11: =IF(OR(AND(ISNUMBER(L11),N(Stromkreisliste!K11)>0,OR(L11>N(Stromkreisliste!K11),L11<0.5*N(Stromkreisliste!K11))),AND(ISNUMBER(M11),M11>$J$5),AND(ISNUMBER(N11),N11>$L$5)),1,0) | U11: =IF(O11="links",1,0)
A12: =IF(Stromkreisliste!B12="","",ROW()-6) | B12: =IF(Stromkreisliste!B12="","",Stromkreisliste!B12) | C12: =IF(Stromkreisliste!B12="","",Stromkreisliste!P12&IF(AND(Stromkreisliste!P12<>"",Stromkreisliste!Q12<>"")," – ","")&Stromkreisliste!Q12) | D12: =IF(Stromkreisliste!B12="","",IF(Stromkreisliste!F12="FI/RCD","FI "&Stromkreisliste!H12&" A / "&Stromkreisliste!K12&" mA",IF(Stromkreisliste!F12="FI/LS (RCBO)","FI/LS "&Stromkreisliste!G12&Stromkreisliste!H12&" / "&Stromkreisliste!K12&" mA",IF(Stromkreisliste!G12="",Stromkreisliste!F12&IF(Stromkreisliste!H12="",""," "&Stromkreisliste!H12&" A"),Stromkreisliste!G12&Stromkreisliste!H12)))) | E12: =IF(Stromkreisliste!B12="","",TRIM(Stromkreisliste!M12&" "&Stromkreisliste!N12)) | J12: =IF(N(I12)>0,$D$5/I12,"") | K12: =IF(OR(Stromkreisliste!B12="",N(Stromkreisliste!H12)=0),"",IFERROR($H$5*$D$5/(Stromkreisliste!H12*INDEX({5,10,20,14,3},MATCH(Stromkreisliste!G12,{"B","C","D","K","Z"},0))),"")) | P12: =IF(COUNTA(F12:I12,L12:O12)=0,"",IF(R12+S12+T12+U12>0,"n.i.O.","i.O.")) | R12: =IF(OR(AND(ISNUMBER(F12),F12<$F$5),AND(ISNUMBER(G12),G12<$F$5)),1,0) | S12: =IF(AND(ISNUMBER(I12),N(K12)>0,I12>N(K12)),1,0) | T12: =IF(OR(AND(ISNUMBER(L12),N(Stromkreisliste!K12)>0,OR(L12>N(Stromkreisliste!K12),L12<0.5*N(Stromkreisliste!K12))),AND(ISNUMBER(M12),M12>$J$5),AND(ISNUMBER(N12),N12>$L$5)),1,0) | U12: =IF(O12="links",1,0)
A13: =IF(Stromkreisliste!B13="","",ROW()-6) | B13: =IF(Stromkreisliste!B13="","",Stromkreisliste!B13) | C13: =IF(Stromkreisliste!B13="","",Stromkreisliste!P13&IF(AND(Stromkreisliste!P13<>"",Stromkreisliste!Q13<>"")," – ","")&Stromkreisliste!Q13) | D13: =IF(Stromkreisliste!B13="","",IF(Stromkreisliste!F13="FI/RCD","FI "&Stromkreisliste!H13&" A / "&Stromkreisliste!K13&" mA",IF(Stromkreisliste!F13="FI/LS (RCBO)","FI/LS "&Stromkreisliste!G13&Stromkreisliste!H13&" / "&Stromkreisliste!K13&" mA",IF(Stromkreisliste!G13="",Stromkreisliste!F13&IF(Stromkreisliste!H13="",""," "&Stromkreisliste!H13&" A"),Stromkreisliste!G13&Stromkreisliste!H13)))) | E13: =IF(Stromkreisliste!B13="","",TRIM(Stromkreisliste!M13&" "&Stromkreisliste!N13)) | J13: =IF(N(I13)>0,$D$5/I13,"") | K13: =IF(OR(Stromkreisliste!B13="",N(Stromkreisliste!H13)=0),"",IFERROR($H$5*$D$5/(Stromkreisliste!H13*INDEX({5,10,20,14,3},MATCH(Stromkreisliste!G13,{"B","C","D","K","Z"},0))),"")) | P13: =IF(COUNTA(F13:I13,L13:O13)=0,"",IF(R13+S13+T13+U13>0,"n.i.O.","i.O.")) | R13: =IF(OR(AND(ISNUMBER(F13),F13<$F$5),AND(ISNUMBER(G13),G13<$F$5)),1,0) | S13: =IF(AND(ISNUMBER(I13),N(K13)>0,I13>N(K13)),1,0) | T13: =IF(OR(AND(ISNUMBER(L13),N(Stromkreisliste!K13)>0,OR(L13>N(Stromkreisliste!K13),L13<0.5*N(Stromkreisliste!K13))),AND(ISNUMBER(M13),M13>$J$5),AND(ISNUMBER(N13),N13>$L$5)),1,0) | U13: =IF(O13="links",1,0)
A14: =IF(Stromkreisliste!B14="","",ROW()-6) | B14: =IF(Stromkreisliste!B14="","",Stromkreisliste!B14) | C14: =IF(Stromkreisliste!B14="","",Stromkreisliste!P14&IF(AND(Stromkreisliste!P14<>"",Stromkreisliste!Q14<>"")," – ","")&Stromkreisliste!Q14) | D14: =IF(Stromkreisliste!B14="","",IF(Stromkreisliste!F14="FI/RCD","FI "&Stromkreisliste!H14&" A / "&Stromkreisliste!K14&" mA",IF(Stromkreisliste!F14="FI/LS (RCBO)","FI/LS "&Stromkreisliste!G14&Stromkreisliste!H14&" / "&Stromkreisliste!K14&" mA",IF(Stromkreisliste!G14="",Stromkreisliste!F14&IF(Stromkreisliste!H14="",""," "&Stromkreisliste!H14&" A"),Stromkreisliste!G14&Stromkreisliste!H14)))) | E14: =IF(Stromkreisliste!B14="","",TRIM(Stromkreisliste!M14&" "&Stromkreisliste!N14)) | J14: =IF(N(I14)>0,$D$5/I14,"") | K14: =IF(OR(Stromkreisliste!B14="",N(Stromkreisliste!H14)=0),"",IFERROR($H$5*$D$5/(Stromkreisliste!H14*INDEX({5,10,20,14,3},MATCH(Stromkreisliste!G14,{"B","C","D","K","Z"},0))),"")) | P14: =IF(COUNTA(F14:I14,L14:O14)=0,"",IF(R14+S14+T14+U14>0,"n.i.O.","i.O.")) | R14: =IF(OR(AND(ISNUMBER(F14),F14<$F$5),AND(ISNUMBER(G14),G14<$F$5)),1,0) | S14: =IF(AND(ISNUMBER(I14),N(K14)>0,I14>N(K14)),1,0) | T14: =IF(OR(AND(ISNUMBER(L14),N(Stromkreisliste!K14)>0,OR(L14>N(Stromkreisliste!K14),L14<0.5*N(Stromkreisliste!K14))),AND(ISNUMBER(M14),M14>$J$5),AND(ISNUMBER(N14),N14>$L$5)),1,0) | U14: =IF(O14="links",1,0)
A15: =IF(Stromkreisliste!B15="","",ROW()-6) | B15: =IF(Stromkreisliste!B15="","",Stromkreisliste!B15) | C15: =IF(Stromkreisliste!B15="","",Stromkreisliste!P15&IF(AND(Stromkreisliste!P15<>"",Stromkreisliste!Q15<>"")," – ","")&Stromkreisliste!Q15) | D15: =IF(Stromkreisliste!B15="","",IF(Stromkreisliste!F15="FI/RCD","FI "&Stromkreisliste!H15&" A / "&Stromkreisliste!K15&" mA",IF(Stromkreisliste!F15="FI/LS (RCBO)","FI/LS "&Stromkreisliste!G15&Stromkreisliste!H15&" / "&Stromkreisliste!K15&" mA",IF(Stromkreisliste!G15="",Stromkreisliste!F15&IF(Stromkreisliste!H15="",""," "&Stromkreisliste!H15&" A"),Stromkreisliste!G15&Stromkreisliste!H15)))) | E15: =IF(Stromkreisliste!B15="","",TRIM(Stromkreisliste!M15&" "&Stromkreisliste!N15)) | J15: =IF(N(I15)>0,$D$5/I15,"") | K15: =IF(OR(Stromkreisliste!B15="",N(Stromkreisliste!H15)=0),"",IFERROR($H$5*$D$5/(Stromkreisliste!H15*INDEX({5,10,20,14,3},MATCH(Stromkreisliste!G15,{"B","C","D","K","Z"},0))),"")) | P15: =IF(COUNTA(F15:I15,L15:O15)=0,"",IF(R15+S15+T15+U15>0,"n.i.O.","i.O.")) | R15: =IF(OR(AND(ISNUMBER(F15),F15<$F$5),AND(ISNUMBER(G15),G15<$F$5)),1,0) | S15: =IF(AND(ISNUMBER(I15),N(K15)>0,I15>N(K15)),1,0) | T15: =IF(OR(AND(ISNUMBER(L15),N(Stromkreisliste!K15)>0,OR(L15>N(Stromkreisliste!K15),L15<0.5*N(Stromkreisliste!K15))),AND(ISNUMBER(M15),M15>$J$5),AND(ISNUMBER(N15),N15>$L$5)),1,0) | U15: =IF(O15="links",1,0)
A16: =IF(Stromkreisliste!B16="","",ROW()-6) | B16: =IF(Stromkreisliste!B16="","",Stromkreisliste!B16) | C16: =IF(Stromkreisliste!B16="","",Stromkreisliste!P16&IF(AND(Stromkreisliste!P16<>"",Stromkreisliste!Q16<>"")," – ","")&Stromkreisliste!Q16) | D16: =IF(Stromkreisliste!B16="","",IF(Stromkreisliste!F16="FI/RCD","FI "&Stromkreisliste!H16&" A / "&Stromkreisliste!K16&" mA",IF(Stromkreisliste!F16="FI/LS (RCBO)","FI/LS "&Stromkreisliste!G16&Stromkreisliste!H16&" / "&Stromkreisliste!K16&" mA",IF(Stromkreisliste!G16="",Stromkreisliste!F16&IF(Stromkreisliste!H16="",""," "&Stromkreisliste!H16&" A"),Stromkreisliste!G16&Stromkreisliste!H16)))) | E16: =IF(Stromkreisliste!B16="","",TRIM(Stromkreisliste!M16&" "&Stromkreisliste!N16)) | J16: =IF(N(I16)>0,$D$5/I16,"") | K16: =IF(OR(Stromkreisliste!B16="",N(Stromkreisliste!H16)=0),"",IFERROR($H$5*$D$5/(Stromkreisliste!H16*INDEX({5,10,20,14,3},MATCH(Stromkreisliste!G16,{"B","C","D","K","Z"},0))),"")) | P16: =IF(COUNTA(F16:I16,L16:O16)=0,"",IF(R16+S16+T16+U16>0,"n.i.O.","i.O.")) | R16: =IF(OR(AND(ISNUMBER(F16),F16<$F$5),AND(ISNUMBER(G16),G16<$F$5)),1,0) | S16: =IF(AND(ISNUMBER(I16),N(K16)>0,I16>N(K16)),1,0) | T16: =IF(OR(AND(ISNUMBER(L16),N(Stromkreisliste!K16)>0,OR(L16>N(Stromkreisliste!K16),L16<0.5*N(Stromkreisliste!K16))),AND(ISNUMBER(M16),M16>$J$5),AND(ISNUMBER(N16),N16>$L$5)),1,0) | U16: =IF(O16="links",1,0)
A17: =IF(Stromkreisliste!B17="","",ROW()-6) | B17: =IF(Stromkreisliste!B17="","",Stromkreisliste!B17) | C17: =IF(Stromkreisliste!B17="","",Stromkreisliste!P17&IF(AND(Stromkreisliste!P17<>"",Stromkreisliste!Q17<>"")," – ","")&Stromkreisliste!Q17) | D17: =IF(Stromkreisliste!B17="","",IF(Stromkreisliste!F17="FI/RCD","FI "&Stromkreisliste!H17&" A / "&Stromkreisliste!K17&" mA",IF(Stromkreisliste!F17="FI/LS (RCBO)","FI/LS "&Stromkreisliste!G17&Stromkreisliste!H17&" / "&Stromkreisliste!K17&" mA",IF(Stromkreisliste!G17="",Stromkreisliste!F17&IF(Stromkreisliste!H17="",""," "&Stromkreisliste!H17&" A"),Stromkreisliste!G17&Stromkreisliste!H17)))) | E17: =IF(Stromkreisliste!B17="","",TRIM(Stromkreisliste!M17&" "&Stromkreisliste!N17)) | J17: =IF(N(I17)>0,$D$5/I17,"") | K17: =IF(OR(Stromkreisliste!B17="",N(Stromkreisliste!H17)=0),"",IFERROR($H$5*$D$5/(Stromkreisliste!H17*INDEX({5,10,20,14,3},MATCH(Stromkreisliste!G17,{"B","C","D","K","Z"},0))),"")) | P17: =IF(COUNTA(F17:I17,L17:O17)=0,"",IF(R17+S17+T17+U17>0,"n.i.O.","i.O.")) | R17: =IF(OR(AND(ISNUMBER(F17),F17<$F$5),AND(ISNUMBER(G17),G17<$F$5)),1,0) | S17: =IF(AND(ISNUMBER(I17),N(K17)>0,I17>N(K17)),1,0) | T17: =IF(OR(AND(ISNUMBER(L17),N(Stromkreisliste!K17)>0,OR(L17>N(Stromkreisliste!K17),L17<0.5*N(Stromkreisliste!K17))),AND(ISNUMBER(M17),M17>$J$5),AND(ISNUMBER(N17),N17>$L$5)),1,0) | U17: =IF(O17="links",1,0)
A18: =IF(Stromkreisliste!B18="","",ROW()-6) | B18: =IF(Stromkreisliste!B18="","",Stromkreisliste!B18) | C18: =IF(Stromkreisliste!B18="","",Stromkreisliste!P18&IF(AND(Stromkreisliste!P18<>"",Stromkreisliste!Q18<>"")," – ","")&Stromkreisliste!Q18) | D18: =IF(Stromkreisliste!B18="","",IF(Stromkreisliste!F18="FI/RCD","FI "&Stromkreisliste!H18&" A / "&Stromkreisliste!K18&" mA",IF(Stromkreisliste!F18="FI/LS (RCBO)","FI/LS "&Stromkreisliste!G18&Stromkreisliste!H18&" / "&Stromkreisliste!K18&" mA",IF(Stromkreisliste!G18="",Stromkreisliste!F18&IF(Stromkreisliste!H18="",""," "&Stromkreisliste!H18&" A"),Stromkreisliste!G18&Stromkreisliste!H18)))) | E18: =IF(Stromkreisliste!B18="","",TRIM(Stromkreisliste!M18&" "&Stromkreisliste!N18)) | J18: =IF(N(I18)>0,$D$5/I18,"") | K18: =IF(OR(Stromkreisliste!B18="",N(Stromkreisliste!H18)=0),"",IFERROR($H$5*$D$5/(Stromkreisliste!H18*INDEX({5,10,20,14,3},MATCH(Stromkreisliste!G18,{"B","C","D","K","Z"},0))),"")) | P18: =IF(COUNTA(F18:I18,L18:O18)=0,"",IF(R18+S18+T18+U18>0,"n.i.O.","i.O.")) | R18: =IF(OR(AND(ISNUMBER(F18),F18<$F$5),AND(ISNUMBER(G18),G18<$F$5)),1,0) | S18: =IF(AND(ISNUMBER(I18),N(K18)>0,I18>N(K18)),1,0) | T18: =IF(OR(AND(ISNUMBER(L18),N(Stromkreisliste!K18)>0,OR(L18>N(Stromkreisliste!K18),L18<0.5*N(Stromkreisliste!K18))),AND(ISNUMBER(M18),M18>$J$5),AND(ISNUMBER(N18),N18>$L$5)),1,0) | U18: =IF(O18="links",1,0)
... A56: =IF(Stromkreisliste!B56="","",ROW()-6) | B56: =IF(Stromkreisliste!B56="","",Stromkreisliste!B56) | C56: =IF(Stromkreisliste!B56="","",Stromkreisliste!P56&IF(AND(Stromkreisliste!P56<>"",Stromkreisliste!Q56<>"")," – ","")&Stromkreisliste!Q56) | D56: =IF(Stromkreisliste!B56="","",IF(Stromkreisliste!F56="FI/RCD","FI "&Stromkreisliste!H56&" A / "&Stromkreisliste!K56&" mA",IF(Stromkreisliste!F56="FI/LS (RCBO)","FI/LS "&Stromkreisliste!G56&Stromkreisliste!H56&" / "&Stromkreisliste!K56&" mA",IF(Stromkreisliste!G56="",Stromkreisliste!F56&IF(Stromkreisliste!H56="",""," "&Stromkreisliste!H56&" A"),Stromkreisliste!G56&Stromkreisliste!H56)))) | E56: =IF(Stromkreisliste!B56="","",TRIM(Stromkreisliste!M56&" "&Stromkreisliste!N56)) | J56: =IF(N(I56)>0,$D$5/I56,"") | K56: =IF(OR(Stromkreisliste!B56="",N(Stromkreisliste!H56)=0),"",IFERROR($H$5*$D$5/(Stromkreisliste!H56*INDEX({5,10,20,14,3},MATCH(Stromkreisliste!G56,{"B","C","D","K","Z"},0))),"")) | P56: =IF(COUNTA(F56:I56,L56:O56)=0,"",IF(R56+S56+T56+U56>0,"n.i.O.","i.O.")) | R56: =IF(OR(AND(ISNUMBER(F56),F56<$F$5),AND(ISNUMBER(G56),G56<$F$5)),1,0) | S56: =IF(AND(ISNUMBER(I56),N(K56)>0,I56>N(K56)),1,0) | T56: =IF(OR(AND(ISNUMBER(L56),N(Stromkreisliste!K56)>0,OR(L56>N(Stromkreisliste!K56),L56<0.5*N(Stromkreisliste!K56))),AND(ISNUMBER(M56),M56>$J$5),AND(ISNUMBER(N56),N56>$L$5)),1,0) | U56: =IF(O56="links",1,0)
B59: Ort, Datum | I59: ="Unterschrift Prüfer: "&Anlage!B26
